Traceback (most recent call last):
  File "/Users/yirenlu/modal-examples/06_gpu_and_ml/dreambooth/dreambooth_app.py", line 651, in run
    evaluate_model(
  File "/Users/yirenlu/modal-examples/06_gpu_and_ml/dreambooth/dreambooth_app.py", line 423, in evaluate_model
    for image, prompt in Model(hyperparameter_model_dir).inference.starmap(
  File "/opt/homebrew/lib/python3.11/site-packages/modal/_utils/async_utils.py", line 390, in __iter__
    for output in run_async_gen(runner, self._async_iterable):
  File "/opt/homebrew/lib/python3.11/site-packages/modal/_utils/async_utils.py", line 470, in run_async_gen
    next_yield = runner.run(gen.asend(next_send))  # type: ignore[arg-type]
                 ^^^^^^^^^^^^^^^^^^^^^^^^^^^^^^^^
  File "/opt/homebrew/lib/python3.11/site-packages/synchronicity/async_utils.py", line 85, in run
    return self._loop.run_until_complete(wrapper_coro())
           ^^^^^^^^^^^^^^^^^^^^^^^^^^^^^^^^^^^^^^^^^^^^^
  File "/opt/homebrew/Cellar/python@3.11/3.11.9/Frameworks/Python.framework/Versions/3.11/lib/python3.11/asyncio/base_events.py", line 654, in run_until_complete
    return future.result()
           ^^^^^^^^^^^^^^^
  File "/opt/homebrew/lib/python3.11/site-packages/synchronicity/async_utils.py", line 51, in wrapper_coro
    return await coro_task
           ^^^^^^^^^^^^^^^
  File "/opt/homebrew/lib/python3.11/site-packages/modal/_utils/async_utils.py", line 313, in asend
    return await self.gen.asend(value)
           ^^^^^^^^^^^^^^^^^^^^^^^^^^^
  File "/opt/homebrew/lib/python3.11/site-packages/modal/parallel_map.py", line 396, in _starmap_async
    async for output in self._map.aio(raw_input_queue, order_outputs, return_exceptions):  # type: ignore[reportFunctionMemberAccess]
  File "/opt/homebrew/lib/python3.11/site-packages/synchronicity/synchronizer.py", line 426, in _run_generator_async
    raise uc_exc.exc
  File "<ta-01JCKWS5HXNMNH6R07K7PS4ANP>:/root/dreambooth_app.py", line 449, in load_model
  File "<ta-01JCKWS5HXNMNH6R07K7PS4ANP>:/usr/local/lib/python3.10/site-packages/huggingface_hub/utils/_validators.py", line 114, in _inner_fn
  File "<ta-01JCKWS5HXNMNH6R07K7PS4ANP>:/root/src/diffusers/pipelines/pipeline_utils.py", line 753, in from_pretrained
  File "<ta-01JCKWS5HXNMNH6R07K7PS4ANP>:/usr/local/lib/python3.10/site-packages/huggingface_hub/utils/_validators.py", line 114, in _inner_fn
  File "<ta-01JCKWS5HXNMNH6R07K7PS4ANP>:/root/src/diffusers/configuration_utils.py", line 373, in load_config
OSError: Error no file named model_index.json found in directory /model/lr_8e-05_steps_500_rank_4.
